[W 2025-10-06 21:31:05.296 ServerApp] ServerApp.password config is deprecated in 2.0. Use PasswordIdentityProvider.hashed_password.
[I 2025-10-06 21:31:05.456 ServerApp] jupyter_lsp | extension was successfully linked.
[I 2025-10-06 21:31:05.462 ServerApp] jupyter_server_terminals | extension was successfully linked.
[I 2025-10-06 21:31:05.468 ServerApp] jupyterlab | extension was successfully linked.
[I 2025-10-06 21:31:05.474 ServerApp] nbclassic | extension was successfully linked.
[I 2025-10-06 21:31:06.534 ServerApp] notebook_shim | extension was successfully linked.
[I 2025-10-06 21:31:06.644 ServerApp] notebook_shim | extension was successfully loaded.
[I 2025-10-06 21:31:06.647 ServerApp] jupyter_lsp | extension was successfully loaded.
[I 2025-10-06 21:31:06.649 ServerApp] jupyter_server_terminals | extension was successfully loaded.
[I 2025-10-06 21:31:06.669 LabApp] JupyterLab extension loaded from /home/kayvans/.local/lib/python3.10/site-packages/jupyterlab
[I 2025-10-06 21:31:06.669 LabApp] JupyterLab application directory is /home/kayvans/.local/share/jupyter/lab
[I 2025-10-06 21:31:06.671 LabApp] Extension Manager is 'pypi'.
[I 2025-10-06 21:31:07.105 ServerApp] jupyterlab | extension was successfully loaded.
[I 2025-10-06 21:31:07.129 ServerApp] nbclassic | extension was successfully loaded.
[I 2025-10-06 21:31:07.130 ServerApp] Serving notebooks from local directory: /home/kayvans/time-series-forecasting
[I 2025-10-06 21:31:07.130 ServerApp] Jupyter Server 2.16.0 is running at:
[I 2025-10-06 21:31:07.130 ServerApp] http://cs320:2020/lab
[I 2025-10-06 21:31:07.130 ServerApp]     http://127.0.0.1:2020/lab
[I 2025-10-06 21:31:07.130 ServerApp] Use Control-C to stop this server and shut down all kernels (twice to skip confirmation).
[I 2025-10-06 21:31:07.168 ServerApp] Skipped non-installed server(s): bash-language-server, dockerfile-language-server-nodejs, javascript-typescript-langserver, jedi-language-server, julia-language-server, pyright, python-language-server, python-lsp-server, r-languageserver, sql-language-server, texlab, typescript-language-server, unified-language-server, vscode-css-languageserver-bin, vscode-html-languageserver-bin, vscode-json-languageserver-bin, yaml-language-server
[I 2025-10-06 21:31:08.058 ServerApp] 302 GET / (@72.33.2.38) 1.13ms
[W 2025-10-06 21:31:09.319 LabApp] Could not determine jupyterlab build status without nodejs
[W 2025-10-06 21:31:09.534 ServerApp] 404 GET /api/contents/cs320/labs/Lab5/dfs-class/README.md?content=0&hash=0&1759786269500 (9563e4435fb94f55afdfdbad49cdc37d@72.33.2.38) 2.45ms referer=http://34.68.122.52:2020/lab?
[W 2025-10-06 21:31:09.534 ServerApp] 404 GET /api/contents/cs320/labs/Lab5/dfs-class/README.md?content=0&hash=0&1759786269500 (72.33.2.38): No such file or directory: cs320/labs/Lab5/dfs-class/README.md
[W 2025-10-06 21:31:09.536 ServerApp] 404 GET /api/contents/cs320/labs/Lab5/dfs-class?content=0&hash=0&1759786269500 (9563e4435fb94f55afdfdbad49cdc37d@72.33.2.38) 1.72ms referer=http://34.68.122.52:2020/lab?
[W 2025-10-06 21:31:09.537 ServerApp] 404 GET /api/contents/cs320/labs/Lab5/dfs-class?content=0&hash=0&1759786269500 (72.33.2.38): No such file or directory: cs320/labs/Lab5/dfs-class
[W 2025-10-06 21:31:09.537 ServerApp] 404 GET /api/contents/cs320/projects/mp4?content=0&hash=0&1759786269500 (9563e4435fb94f55afdfdbad49cdc37d@72.33.2.38) 2.24ms referer=http://34.68.122.52:2020/lab?
[W 2025-10-06 21:31:09.538 ServerApp] 404 GET /api/contents/cs320/projects/mp4?content=0&hash=0&1759786269500 (72.33.2.38): No such file or directory: cs320/projects/mp4
[W 2025-10-06 21:31:09.540 ServerApp] 404 GET /api/contents/cs320/projects/mp4/scrape.py?content=0&hash=0&1759786269500 (9563e4435fb94f55afdfdbad49cdc37d@72.33.2.38) 1.83ms referer=http://34.68.122.52:2020/lab?
[W 2025-10-06 21:31:09.540 ServerApp] 404 GET /api/contents/cs320/projects/mp4/scrape.py?content=0&hash=0&1759786269500 (72.33.2.38): No such file or directory: cs320/projects/mp4/scrape.py
[W 2025-10-06 21:31:09.541 ServerApp] 404 GET /api/contents/cs320/labs/Lab5/dfs-class/debug.ipynb?content=0&hash=0&1759786269500 (9563e4435fb94f55afdfdbad49cdc37d@72.33.2.38) 2.43ms referer=http://34.68.122.52:2020/lab?
[W 2025-10-06 21:31:09.541 ServerApp] 404 GET /api/contents/cs320/labs/Lab5/dfs-class/debug.ipynb?content=0&hash=0&1759786269500 (72.33.2.38): No such file or directory: cs320/labs/Lab5/dfs-class/debug.ipynb
[W 2025-10-06 21:31:09.554 ServerApp] 404 GET /api/contents/cs320/labs/Lab5/dfs-class/Untitled.ipynb?content=0&hash=0&1759786269500 (9563e4435fb94f55afdfdbad49cdc37d@72.33.2.38) 1.42ms referer=http://34.68.122.52:2020/lab?
[W 2025-10-06 21:31:09.555 ServerApp] 404 GET /api/contents/cs320/labs/Lab5/dfs-class/Untitled.ipynb?content=0&hash=0&1759786269500 (72.33.2.38): No such file or directory: cs320/labs/Lab5/dfs-class/Untitled.ipynb
[W 2025-10-06 21:31:09.561 ServerApp] 404 GET /api/contents/cs320/labs/Lab5/lab5.ipynb?content=0&hash=0&1759786269500 (9563e4435fb94f55afdfdbad49cdc37d@72.33.2.38) 1.81ms referer=http://34.68.122.52:2020/lab?
[W 2025-10-06 21:31:09.561 ServerApp] 404 GET /api/contents/cs320/labs/Lab5/lab5.ipynb?content=0&hash=0&1759786269500 (72.33.2.38): No such file or directory: cs320/labs/Lab5/lab5.ipynb
[W 2025-10-06 21:31:09.562 ServerApp] 404 GET /api/contents/cs320/labs/Lab5?content=0&hash=0&1759786269500 (9563e4435fb94f55afdfdbad49cdc37d@72.33.2.38) 2.31ms referer=http://34.68.122.52:2020/lab?
[W 2025-10-06 21:31:09.562 ServerApp] 404 GET /api/contents/cs320/labs/Lab5?content=0&hash=0&1759786269500 (72.33.2.38): No such file or directory: cs320/labs/Lab5
[W 2025-10-06 21:31:09.564 ServerApp] 404 GET /api/contents/cs320/projects/mp3?content=0&hash=0&1759786269500 (9563e4435fb94f55afdfdbad49cdc37d@72.33.2.38) 1.19ms referer=http://34.68.122.52:2020/lab?
[W 2025-10-06 21:31:09.564 ServerApp] 404 GET /api/contents/cs320/projects/mp3?content=0&hash=0&1759786269500 (72.33.2.38): No such file or directory: cs320/projects/mp3
[W 2025-10-06 21:31:09.566 ServerApp] 404 GET /api/contents/cs320/projects/mp3/mp3.ipynb?content=0&hash=0&1759786269500 (9563e4435fb94f55afdfdbad49cdc37d@72.33.2.38) 1.36ms referer=http://34.68.122.52:2020/lab?
[W 2025-10-06 21:31:09.566 ServerApp] 404 GET /api/contents/cs320/projects/mp3/mp3.ipynb?content=0&hash=0&1759786269500 (72.33.2.38): No such file or directory: cs320/projects/mp3/mp3.ipynb
[W 2025-10-06 21:31:09.567 ServerApp] 404 GET /api/contents/cs320/projects/mp4/scrape.py?content=0&hash=0&1759786269500 (9563e4435fb94f55afdfdbad49cdc37d@72.33.2.38) 1.92ms referer=http://34.68.122.52:2020/lab?
[W 2025-10-06 21:31:09.567 ServerApp] 404 GET /api/contents/cs320/projects/mp4/scrape.py?content=0&hash=0&1759786269500 (72.33.2.38): No such file or directory: cs320/projects/mp4/scrape.py
[W 2025-10-06 21:31:09.580 ServerApp] 404 GET /api/contents/cs320/labs/Lab5/dfs-class/README.md?content=0&hash=0&1759786269500 (9563e4435fb94f55afdfdbad49cdc37d@72.33.2.38) 2.19ms referer=http://34.68.122.52:2020/lab?
[W 2025-10-06 21:31:09.581 ServerApp] 404 GET /api/contents/cs320/labs/Lab5/dfs-class/README.md?content=0&hash=0&1759786269500 (72.33.2.38): No such file or directory: cs320/labs/Lab5/dfs-class/README.md
[W 2025-10-06 21:31:09.590 ServerApp] 404 GET /api/contents/cs320/labs/Lab5/lab5.ipynb?content=0&hash=0&1759786269500 (9563e4435fb94f55afdfdbad49cdc37d@72.33.2.38) 1.60ms referer=http://34.68.122.52:2020/lab?
[W 2025-10-06 21:31:09.590 ServerApp] 404 GET /api/contents/cs320/labs/Lab5/lab5.ipynb?content=0&hash=0&1759786269500 (72.33.2.38): No such file or directory: cs320/labs/Lab5/lab5.ipynb
[W 2025-10-06 21:31:09.592 ServerApp] 404 GET /api/contents/cs320/projects/mp3/mp3.ipynb?content=0&hash=0&1759786269500 (9563e4435fb94f55afdfdbad49cdc37d@72.33.2.38) 1.27ms referer=http://34.68.122.52:2020/lab?
[W 2025-10-06 21:31:09.592 ServerApp] 404 GET /api/contents/cs320/projects/mp3/mp3.ipynb?content=0&hash=0&1759786269500 (72.33.2.38): No such file or directory: cs320/projects/mp3/mp3.ipynb
[W 2025-10-06 21:31:09.594 ServerApp] 404 GET /api/contents/cs320/labs/Lab4/bst-groups/README.md?content=0&hash=0&1759786269500 (9563e4435fb94f55afdfdbad49cdc37d@72.33.2.38) 1.27ms referer=http://34.68.122.52:2020/lab?
[W 2025-10-06 21:31:09.594 ServerApp] 404 GET /api/contents/cs320/labs/Lab4/bst-groups/README.md?content=0&hash=0&1759786269500 (72.33.2.38): No such file or directory: cs320/labs/Lab4/bst-groups/README.md
[W 2025-10-06 21:31:09.596 ServerApp] 404 GET /api/contents/cs320/projects/mp3/search.py?content=0&hash=0&1759786269500 (9563e4435fb94f55afdfdbad49cdc37d@72.33.2.38) 1.47ms referer=http://34.68.122.52:2020/lab?
[W 2025-10-06 21:31:09.597 ServerApp] 404 GET /api/contents/cs320/projects/mp3/search.py?content=0&hash=0&1759786269500 (72.33.2.38): No such file or directory: cs320/projects/mp3/search.py
[W 2025-10-06 21:31:09.598 ServerApp] 404 GET /api/contents/cs320/projects/mp3/loans.py?content=0&hash=0&1759786269500 (9563e4435fb94f55afdfdbad49cdc37d@72.33.2.38) 2.37ms referer=http://34.68.122.52:2020/lab?
[W 2025-10-06 21:31:09.598 ServerApp] 404 GET /api/contents/cs320/projects/mp3/loans.py?content=0&hash=0&1759786269500 (72.33.2.38): No such file or directory: cs320/projects/mp3/loans.py
[W 2025-10-06 21:31:09.605 ServerApp] 404 GET /api/contents/cs320/labs/Lab4/README.md?content=0&hash=0&1759786269500 (9563e4435fb94f55afdfdbad49cdc37d@72.33.2.38) 1.65ms referer=http://34.68.122.52:2020/lab?
[W 2025-10-06 21:31:09.605 ServerApp] 404 GET /api/contents/cs320/labs/Lab4/README.md?content=0&hash=0&1759786269500 (72.33.2.38): No such file or directory: cs320/labs/Lab4/README.md
[W 2025-10-06 21:31:09.614 ServerApp] 404 GET /api/contents/cs320/labs/Lab5/dfs-class/debug.ipynb?content=0&hash=0&1759786269501 (9563e4435fb94f55afdfdbad49cdc37d@72.33.2.38) 1.52ms referer=http://34.68.122.52:2020/lab?
[W 2025-10-06 21:31:09.614 ServerApp] 404 GET /api/contents/cs320/labs/Lab5/dfs-class/debug.ipynb?content=0&hash=0&1759786269501 (72.33.2.38): No such file or directory: cs320/labs/Lab5/dfs-class/debug.ipynb
[W 2025-10-06 21:31:10.798 ServerApp] 404 GET /api/contents/cs320/labs/Lab5?1759786270764 (9563e4435fb94f55afdfdbad49cdc37d@72.33.2.38) 1.67ms referer=http://34.68.122.52:2020/lab?
[W 2025-10-06 21:31:10.798 ServerApp] 404 GET /api/contents/cs320/labs/Lab5?1759786270764 (72.33.2.38): No such file or directory: cs320/labs/Lab5
[I 2025-10-06 21:37:15.883 ServerApp] Creating new notebook in 
[I 2025-10-06 21:37:17.276 ServerApp] Kernel started: b4c28d6d-743c-4f70-a173-f308146e6462
[I 2025-10-06 21:37:18.689 ServerApp] Connecting to kernel b4c28d6d-743c-4f70-a173-f308146e6462.
[I 2025-10-06 21:37:18.694 ServerApp] Connecting to kernel b4c28d6d-743c-4f70-a173-f308146e6462.
[I 2025-10-06 21:37:18.700 ServerApp] Connecting to kernel b4c28d6d-743c-4f70-a173-f308146e6462.
[W 2025-10-06 21:37:18.704 ServerApp] The websocket_ping_timeout (90000) cannot be longer than the websocket_ping_interval (30000).
    Setting websocket_ping_timeout=30000
[I 2025-10-06 21:37:25.516 ServerApp] Saving file at /Untitled.ipynb
[I 2025-10-06 21:39:25.765 ServerApp] Saving file at /Untitled.ipynb
[I 2025-10-06 21:41:25.999 ServerApp] Saving file at /Untitled.ipynb
[I 2025-10-06 21:42:13.917 ServerApp] Saving file at /Untitled.ipynb
[E 2025-10-06 21:42:13.998 ServerApp] Uncaught exception POST /api/contents/Untitled.ipynb/checkpoints?1759786933964 (72.33.2.38)
    HTTPServerRequest(protocol='http', host='34.68.122.52:2020', method='POST', uri='/api/contents/Untitled.ipynb/checkpoints?1759786933964', version='HTTP/1.1', remote_ip='72.33.2.38')
    Traceback (most recent call last):
      File "/home/kayvans/.local/lib/python3.10/site-packages/tornado/web.py", line 1848, in _execute
        result = await result
      File "/home/kayvans/.local/lib/python3.10/site-packages/jupyter_server/auth/decorator.py", line 73, in inner
        return await out
      File "/home/kayvans/.local/lib/python3.10/site-packages/jupyter_server/services/contents/handlers.py", line 358, in post
        checkpoint = await ensure_async(cm.create_checkpoint(path))
      File "/home/kayvans/.local/lib/python3.10/site-packages/jupyter_core/utils/__init__.py", line 197, in ensure_async
        result = await obj
      File "/home/kayvans/.local/lib/python3.10/site-packages/jupyter_server/services/contents/manager.py", line 1083, in create_checkpoint
        return await self.checkpoints.create_checkpoint(self, path)
      File "/home/kayvans/.local/lib/python3.10/site-packages/jupyter_server/services/contents/filecheckpoints.py", line 145, in create_checkpoint
        await self._copy(src_path, dest_path)
      File "/home/kayvans/.local/lib/python3.10/site-packages/jupyter_server/services/contents/fileio.py", line 470, in _copy
        await async_copy2_safe(src, dest, log=self.log)
      File "/home/kayvans/.local/lib/python3.10/site-packages/jupyter_server/services/contents/fileio.py", line 66, in async_copy2_safe
        await run_sync(shutil.copyfile, src, dst)
      File "/home/kayvans/.local/lib/python3.10/site-packages/anyio/to_thread.py", line 56, in run_sync
        return await get_async_backend().run_sync_in_worker_thread(
      File "/home/kayvans/.local/lib/python3.10/site-packages/anyio/_backends/_asyncio.py", line 2470, in run_sync_in_worker_thread
        return await future
      File "/home/kayvans/.local/lib/python3.10/site-packages/anyio/_backends/_asyncio.py", line 967, in run
        result = context.run(func, *args)
      File "/usr/lib/python3.10/shutil.py", line 254, in copyfile
        with open(src, 'rb') as fsrc:
    FileNotFoundError: [Errno 2] No such file or directory: '/home/kayvans/time-series-forecasting/Untitled.ipynb'
[W 2025-10-06 21:42:14.028 ServerApp] wrote error: 'Unhandled error'
    Traceback (most recent call last):
      File "/home/kayvans/.local/lib/python3.10/site-packages/tornado/web.py", line 1848, in _execute
        result = await result
      File "/home/kayvans/.local/lib/python3.10/site-packages/jupyter_server/auth/decorator.py", line 73, in inner
        return await out
      File "/home/kayvans/.local/lib/python3.10/site-packages/jupyter_server/services/contents/handlers.py", line 358, in post
        checkpoint = await ensure_async(cm.create_checkpoint(path))
      File "/home/kayvans/.local/lib/python3.10/site-packages/jupyter_core/utils/__init__.py", line 197, in ensure_async
        result = await obj
      File "/home/kayvans/.local/lib/python3.10/site-packages/jupyter_server/services/contents/manager.py", line 1083, in create_checkpoint
        return await self.checkpoints.create_checkpoint(self, path)
      File "/home/kayvans/.local/lib/python3.10/site-packages/jupyter_server/services/contents/filecheckpoints.py", line 145, in create_checkpoint
        await self._copy(src_path, dest_path)
      File "/home/kayvans/.local/lib/python3.10/site-packages/jupyter_server/services/contents/fileio.py", line 470, in _copy
        await async_copy2_safe(src, dest, log=self.log)
      File "/home/kayvans/.local/lib/python3.10/site-packages/jupyter_server/services/contents/fileio.py", line 66, in async_copy2_safe
        await run_sync(shutil.copyfile, src, dst)
      File "/home/kayvans/.local/lib/python3.10/site-packages/anyio/to_thread.py", line 56, in run_sync
        return await get_async_backend().run_sync_in_worker_thread(
      File "/home/kayvans/.local/lib/python3.10/site-packages/anyio/_backends/_asyncio.py", line 2470, in run_sync_in_worker_thread
        return await future
      File "/home/kayvans/.local/lib/python3.10/site-packages/anyio/_backends/_asyncio.py", line 967, in run
        result = context.run(func, *args)
      File "/usr/lib/python3.10/shutil.py", line 254, in copyfile
        with open(src, 'rb') as fsrc:
    FileNotFoundError: [Errno 2] No such file or directory: '/home/kayvans/time-series-forecasting/Untitled.ipynb'
[E 2025-10-06 21:42:14.029 ServerApp] {
      "Host": "34.68.122.52:2020",
      "Accept": "*/*",
      "Referer": "http://34.68.122.52:2020/lab/tree/Untitled.ipynb",
      "User-Agent": "Mozilla/5.0 (Macintosh; Intel Mac OS X 10_15_7) AppleWebKit/605.1.15 (KHTML, like Gecko) Version/18.6 Safari/605.1.15"
    }
[E 2025-10-06 21:42:14.030 ServerApp] 500 POST /api/contents/Untitled.ipynb/checkpoints?1759786933964 (9563e4435fb94f55afdfdbad49cdc37d@72.33.2.38) 36.98ms referer=http://34.68.122.52:2020/lab/tree/Untitled.ipynb
[I 2025-10-06 21:44:14.131 ServerApp] Saving file at /time_series_forecasting.ipynb
[I 2025-10-06 22:00:56.801 ServerApp] Saving file at /time_series_forecasting.ipynb
[I 2025-10-06 22:01:47.554 ServerApp] Saving file at /time_series_forecasting.ipynb
[W 2025-10-06 22:02:01.557 ServerApp] 400 GET /api/contents/Microsoft_Stock.csv?type=file&content=1&hash=1&format=text&contentProviderId=undefined&1759788121535 (72.33.2.38): /home/kayvans/time-series-forecasting/Microsoft_Stock.csv is not UTF-8 encoded
[W 2025-10-06 22:02:01.557 ServerApp] wrote error: '/home/kayvans/time-series-forecasting/Microsoft_Stock.csv is not UTF-8 encoded'
    Traceback (most recent call last):
      File "/home/kayvans/.local/lib/python3.10/site-packages/jupyter_server/services/contents/fileio.py", line 562, in _read_file
        (bcontent.decode("utf8"), "text", bcontent)
    UnicodeDecodeError: 'utf-8' codec can't decode byte 0x97 in position 10: invalid start byte
    
    The above exception was the direct cause of the following exception:
    
    Traceback (most recent call last):
      File "/home/kayvans/.local/lib/python3.10/site-packages/tornado/web.py", line 1848, in _execute
        result = await result
      File "/home/kayvans/.local/lib/python3.10/site-packages/jupyter_server/auth/decorator.py", line 73, in inner
        return await out
      File "/home/kayvans/.local/lib/python3.10/site-packages/jupyter_server/services/contents/handlers.py", line 156, in get
        model = await ensure_async(
      File "/home/kayvans/.local/lib/python3.10/site-packages/jupyter_core/utils/__init__.py", line 197, in ensure_async
        result = await obj
      File "/home/kayvans/.local/lib/python3.10/site-packages/jupyter_server/services/contents/filemanager.py", line 926, in get
        model = await self._file_model(
      File "/home/kayvans/.local/lib/python3.10/site-packages/jupyter_server/services/contents/filemanager.py", line 835, in _file_model
        content, format, bytes_content = await self._read_file(os_path, format, raw=True)  # type: ignore[misc]
      File "/home/kayvans/.local/lib/python3.10/site-packages/jupyter_server/services/contents/fileio.py", line 571, in _read_file
        raise HTTPError(
    tornado.web.HTTPError: HTTP 400: bad format (/home/kayvans/time-series-forecasting/Microsoft_Stock.csv is not UTF-8 encoded)
[W 2025-10-06 22:02:01.561 ServerApp] 400 GET /api/contents/Microsoft_Stock.csv?type=file&content=1&hash=1&format=text&contentProviderId=undefined&1759788121535 (9563e4435fb94f55afdfdbad49cdc37d@72.33.2.38) 7.72ms referer=http://34.68.122.52:2020/lab/tree/Microsoft_Stock.csv
[I 2025-10-06 22:03:17.197 ServerApp] Saving file at /time_series_forecasting.ipynb
[W 2025-10-06 22:04:44.111 ServerApp] 400 GET /api/contents/Microsoft_Stock.csv.numbers?type=file&content=1&hash=1&format=text&contentProviderId=undefined&1759788284088 (72.33.2.38): /home/kayvans/time-series-forecasting/Microsoft_Stock.csv.numbers is not UTF-8 encoded
[W 2025-10-06 22:04:44.112 ServerApp] wrote error: '/home/kayvans/time-series-forecasting/Microsoft_Stock.csv.numbers is not UTF-8 encoded'
    Traceback (most recent call last):
      File "/home/kayvans/.local/lib/python3.10/site-packages/jupyter_server/services/contents/fileio.py", line 562, in _read_file
        (bcontent.decode("utf8"), "text", bcontent)
    UnicodeDecodeError: 'utf-8' codec can't decode byte 0x88 in position 11: invalid start byte
    
    The above exception was the direct cause of the following exception:
    
    Traceback (most recent call last):
      File "/home/kayvans/.local/lib/python3.10/site-packages/tornado/web.py", line 1848, in _execute
        result = await result
      File "/home/kayvans/.local/lib/python3.10/site-packages/jupyter_server/auth/decorator.py", line 73, in inner
        return await out
      File "/home/kayvans/.local/lib/python3.10/site-packages/jupyter_server/services/contents/handlers.py", line 156, in get
        model = await ensure_async(
      File "/home/kayvans/.local/lib/python3.10/site-packages/jupyter_core/utils/__init__.py", line 197, in ensure_async
        result = await obj
      File "/home/kayvans/.local/lib/python3.10/site-packages/jupyter_server/services/contents/filemanager.py", line 926, in get
        model = await self._file_model(
      File "/home/kayvans/.local/lib/python3.10/site-packages/jupyter_server/services/contents/filemanager.py", line 835, in _file_model
        content, format, bytes_content = await self._read_file(os_path, format, raw=True)  # type: ignore[misc]
      File "/home/kayvans/.local/lib/python3.10/site-packages/jupyter_server/services/contents/fileio.py", line 571, in _read_file
        raise HTTPError(
    tornado.web.HTTPError: HTTP 400: bad format (/home/kayvans/time-series-forecasting/Microsoft_Stock.csv.numbers is not UTF-8 encoded)
[W 2025-10-06 22:04:44.113 ServerApp] 400 GET /api/contents/Microsoft_Stock.csv.numbers?type=file&content=1&hash=1&format=text&contentProviderId=undefined&1759788284088 (9563e4435fb94f55afdfdbad49cdc37d@72.33.2.38) 5.57ms referer=http://34.68.122.52:2020/lab/tree/Microsoft_Stock.csv.numbers
[I 2025-10-06 22:05:17.655 ServerApp] Saving file at /time_series_forecasting.ipynb
[W 2025-10-06 22:07:18.697 ServerApp] WebSocket ping timeout after 119981 ms.
[I 2025-10-06 22:07:23.701 ServerApp] Starting buffering for b4c28d6d-743c-4f70-a173-f308146e6462:dace6865-dcf5-4885-bd69-e1896f5c0530
[I 2025-10-06 22:08:08.827 ServerApp] 302 GET / (@91.196.152.121) 1.60ms
[I 2025-10-06 22:08:32.281 ServerApp] Connecting to kernel b4c28d6d-743c-4f70-a173-f308146e6462.
[I 2025-10-06 22:08:32.281 ServerApp] Restoring connection for b4c28d6d-743c-4f70-a173-f308146e6462:dace6865-dcf5-4885-bd69-e1896f5c0530
[I 2025-10-06 22:14:14.889 ServerApp] Saving file at /time_series_forecasting.ipynb
[I 2025-10-06 22:14:23.441 ServerApp] Saving file at /time_series_forecasting.ipynb
[I 2025-10-06 22:14:28.872 ServerApp] Saving file at /time_series_forecasting.ipynb
[I 2025-10-06 22:16:04.648 ServerApp] Saving file at /time_series_forecasting.ipynb
[I 2025-10-06 22:16:11.017 ServerApp] Saving file at /time_series_forecasting.ipynb
[I 2025-10-06 22:16:47.326 ServerApp] Saving file at /time_series_forecasting.ipynb
[I 2025-10-06 22:17:17.896 ServerApp] Saving file at /time_series_forecasting.ipynb
[I 2025-10-06 22:17:34.045 LabApp] 302 GET /lab? (@91.196.152.122) 1.47ms
[I 2025-10-06 22:18:00.947 ServerApp] Saving file at /time_series_forecasting.ipynb
[I 2025-10-06 22:18:43.694 ServerApp] Saving file at /time_series_forecasting.ipynb
[I 2025-10-06 22:19:15.051 ServerApp] Saving file at /time_series_forecasting.ipynb
[I 2025-10-06 22:19:21.127 ServerApp] Saving file at /time_series_forecasting.ipynb
[I 2025-10-06 22:19:28.034 ServerApp] Saving file at /time_series_forecasting.ipynb
[I 2025-10-06 22:20:06.743 ServerApp] Saving file at /time_series_forecasting.ipynb
[I 2025-10-06 22:20:16.221 ServerApp] Saving file at /time_series_forecasting.ipynb
[I 2025-10-06 22:22:16.384 ServerApp] Saving file at /time_series_forecasting.ipynb
[I 2025-10-06 22:22:25.051 ServerApp] Saving file at /time_series_forecasting.ipynb
[I 2025-10-06 22:23:00.584 ServerApp] Saving file at /time_series_forecasting.ipynb
[I 2025-10-06 22:23:05.858 ServerApp] Saving file at /time_series_forecasting.ipynb
[I 2025-10-06 22:25:05.996 ServerApp] Saving file at /time_series_forecasting.ipynb
[I 2025-10-06 22:25:09.653 LabApp] 302 GET /lab? (@91.196.152.183) 1.23ms
[I 2025-10-06 22:27:06.200 ServerApp] Saving file at /time_series_forecasting.ipynb
[I 2025-10-06 22:29:06.458 ServerApp] Saving file at /time_series_forecasting.ipynb
[I 2025-10-06 22:30:16.532 ServerApp] Saving file at /time_series_forecasting.ipynb
[I 2025-10-06 22:31:14.354 ServerApp] Saving file at /time_series_forecasting.ipynb
[I 2025-10-06 22:31:33.301 ServerApp] Saving file at /time_series_forecasting.ipynb
[I 2025-10-06 22:33:33.444 ServerApp] Saving file at /time_series_forecasting.ipynb
[I 2025-10-06 22:33:34.360 ServerApp] Saving file at /time_series_forecasting.ipynb
[I 2025-10-06 22:34:34.328 ServerApp] Saving file at /time_series_forecasting.ipynb
[I 2025-10-06 22:35:57.404 ServerApp] Saving file at /time_series_forecasting.ipynb
[I 2025-10-06 22:36:17.958 ServerApp] Saving file at /time_series_forecasting.ipynb
[I 2025-10-06 22:36:32.932 ServerApp] Saving file at /time_series_forecasting.ipynb
[I 2025-10-06 22:38:33.151 ServerApp] Saving file at /time_series_forecasting.ipynb
[I 2025-10-06 22:40:33.266 ServerApp] Saving file at /time_series_forecasting.ipynb
[I 2025-10-06 22:41:40.658 ServerApp] Saving file at /time_series_forecasting.ipynb
[I 2025-10-06 22:49:41.053 ServerApp] Saving file at /time_series_forecasting.ipynb
[I 2025-10-06 22:51:05.096 ServerApp] Saving file at /time_series_forecasting.ipynb
[I 2025-10-06 22:51:08.671 ServerApp] Saving file at /time_series_forecasting.ipynb
[I 2025-10-06 22:51:09.708 ServerApp] Starting buffering for b4c28d6d-743c-4f70-a173-f308146e6462:dace6865-dcf5-4885-bd69-e1896f5c0530
